<?xml version="1.0" ?>
<!-- =================================================================================== -->
<!-- |    This document was autogenerated by xacro from multiple_ready2_educate.xacro  | -->
<!-- |    EDITING THIS FILE BY HAND IS NOT RECOMMENDED                                 | -->
<!-- =================================================================================== -->
<robot name="ready2_educate_multiple_arms">
  <!-- colours based on RAL values given in "FAQ - Colours of robot and robot
       controller", version "KUKA.Tifs | 2010-01-21 |YM| DefaultColorsRobotAndController.doc",
       downloaded 2015-07-18 from
       http://www.kuka.be/main/cservice/faqs/hardware/DefaultColorsRobotAndController.pdf

       all RAL colours converted using http://www.visual-graphics.de/en/customer-care/ral-colours
  -->
  <link name="world"/>
  <link name="right_armbase_link">
    <inertial>
      <mass value="0.01"/>
      <origin xyz="0 0 0"/>
      <inertia ixx="0.001" ixy="0.0" ixz="0.0" iyy="0.001" iyz="0.0" izz="0.001"/>
    </inertial>
    <visual>
      <origin rpy="0 0 0" xyz="0 0 0"/>
      <geometry>
        <mesh filename="file:///home/huang/stogl_workspace/ros_rolling_docker_ws/install/kuka_kr3_support/share/kuka_kr3_support/meshes/kr3r540/visual/base_link.stl"/>
      </geometry>
      <material name="">
        <color rgba="0.5058823529411764 0.47058823529411764 0.38823529411764707 1.0"/>
      </material>
    </visual>
    <collision>
      <origin rpy="0 0 0" xyz="0 0 0"/>
      <geometry>
        <mesh filename="file:///home/huang/stogl_workspace/ros_rolling_docker_ws/install/kuka_kr3_support/share/kuka_kr3_support/meshes/kr3r540/collision/base_link.stl"/>
      </geometry>
    </collision>
  </link>
  <link name="right_armlink_1">
    <inertial>
      <mass value="0.01"/>
      <origin xyz="0 0 0"/>
      <inertia ixx="0.001" ixy="0.0" ixz="0.0" iyy="0.001" iyz="0.0" izz="0.001"/>
    </inertial>
    <visual>
      <origin rpy="0 0 0" xyz="0 0 0"/>
      <geometry>
        <mesh filename="file:///home/huang/stogl_workspace/ros_rolling_docker_ws/install/kuka_kr3_support/share/kuka_kr3_support/meshes/kr3r540/visual/link_1.stl"/>
      </geometry>
      <material name="">
        <color rgba="0.9450980392156862 0.9254901960784314 1.0 1.0"/>
      </material>
    </visual>
    <collision>
      <origin rpy="0 0 0" xyz="0 0 0"/>
      <geometry>
        <mesh filename="file:///home/huang/stogl_workspace/ros_rolling_docker_ws/install/kuka_kr3_support/share/kuka_kr3_support/meshes/kr3r540/collision/link_1.stl"/>
      </geometry>
    </collision>
  </link>
  <link name="right_armlink_2">
    <inertial>
      <mass value="0.01"/>
      <origin xyz="0 0 0"/>
      <inertia ixx="0.001" ixy="0.0" ixz="0.0" iyy="0.001" iyz="0.0" izz="0.001"/>
    </inertial>
    <visual>
      <origin rpy="0 0 0" xyz="0 0 0"/>
      <geometry>
        <mesh filename="file:///home/huang/stogl_workspace/ros_rolling_docker_ws/install/kuka_kr3_support/share/kuka_kr3_support/meshes/kr3r540/visual/link_2.stl"/>
      </geometry>
      <material name="">
        <color rgba="0.9450980392156862 0.9254901960784314 1.0 1.0"/>
      </material>
    </visual>
    <collision>
      <origin rpy="0 0 0" xyz="0 0 0"/>
      <geometry>
        <mesh filename="file:///home/huang/stogl_workspace/ros_rolling_docker_ws/install/kuka_kr3_support/share/kuka_kr3_support/meshes/kr3r540/collision/link_2.stl"/>
      </geometry>
    </collision>
  </link>
  <link name="right_armlink_3">
    <inertial>
      <mass value="0.01"/>
      <origin xyz="0 0 0"/>
      <inertia ixx="0.001" ixy="0.0" ixz="0.0" iyy="0.001" iyz="0.0" izz="0.001"/>
    </inertial>
    <visual>
      <origin rpy="0 0 0" xyz="0 0 0"/>
      <geometry>
        <mesh filename="file:///home/huang/stogl_workspace/ros_rolling_docker_ws/install/kuka_kr3_support/share/kuka_kr3_support/meshes/kr3r540/visual/link_3.stl"/>
      </geometry>
      <material name="">
        <color rgba="0.9450980392156862 0.9254901960784314 1.0 1.0"/>
      </material>
    </visual>
    <collision>
      <origin rpy="0 0 0" xyz="0 0 0"/>
      <geometry>
        <mesh filename="file:///home/huang/stogl_workspace/ros_rolling_docker_ws/install/kuka_kr3_support/share/kuka_kr3_support/meshes/kr3r540/collision/link_3.stl"/>
      </geometry>
    </collision>
  </link>
  <link name="right_armlink_4">
    <inertial>
      <mass value="0.01"/>
      <origin xyz="0 0 0"/>
      <inertia ixx="0.001" ixy="0.0" ixz="0.0" iyy="0.001" iyz="0.0" izz="0.001"/>
    </inertial>
    <visual>
      <origin rpy="0 0 0" xyz="0 0 0"/>
      <geometry>
        <mesh filename="file:///home/huang/stogl_workspace/ros_rolling_docker_ws/install/kuka_kr3_support/share/kuka_kr3_support/meshes/kr3r540/visual/link_4.stl"/>
      </geometry>
      <material name="">
        <color rgba="0.9450980392156862 0.9254901960784314 1.0 1.0"/>
      </material>
    </visual>
    <collision>
      <origin rpy="0 0 0" xyz="0 0 0"/>
      <geometry>
        <mesh filename="file:///home/huang/stogl_workspace/ros_rolling_docker_ws/install/kuka_kr3_support/share/kuka_kr3_support/meshes/kr3r540/collision/link_4.stl"/>
      </geometry>
    </collision>
  </link>
  <link name="right_armlink_5">
    <inertial>
      <mass value="0.01"/>
      <origin xyz="0 0 0"/>
      <inertia ixx="0.001" ixy="0.0" ixz="0.0" iyy="0.001" iyz="0.0" izz="0.001"/>
    </inertial>
    <visual>
      <origin rpy="0 0 0" xyz="0 0 0"/>
      <geometry>
        <mesh filename="file:///home/huang/stogl_workspace/ros_rolling_docker_ws/install/kuka_kr3_support/share/kuka_kr3_support/meshes/kr3r540/visual/link_5.stl"/>
      </geometry>
      <material name="">
        <color rgba="0.9450980392156862 0.9254901960784314 1.0 1.0"/>
      </material>
    </visual>
    <collision>
      <origin rpy="0 0 0" xyz="0 0 0"/>
      <geometry>
        <mesh filename="file:///home/huang/stogl_workspace/ros_rolling_docker_ws/install/kuka_kr3_support/share/kuka_kr3_support/meshes/kr3r540/collision/link_5.stl"/>
      </geometry>
    </collision>
  </link>
  <link name="right_armlink_6">
    <inertial>
      <mass value="0.01"/>
      <origin xyz="0 0 0"/>
      <inertia ixx="0.001" ixy="0.0" ixz="0.0" iyy="0.001" iyz="0.0" izz="0.001"/>
    </inertial>
    <visual>
      <origin rpy="0 0 0" xyz="0 0 0"/>
      <geometry>
        <mesh filename="file:///home/huang/stogl_workspace/ros_rolling_docker_ws/install/kuka_kr3_support/share/kuka_kr3_support/meshes/kr3r540/visual/link_6.stl"/>
      </geometry>
      <material name="">
        <color rgba="0.5058823529411764 0.47058823529411764 0.38823529411764707 1.0"/>
      </material>
    </visual>
    <collision>
      <origin rpy="0 0 0" xyz="0 0 0"/>
      <geometry>
        <mesh filename="file:///home/huang/stogl_workspace/ros_rolling_docker_ws/install/kuka_kr3_support/share/kuka_kr3_support/meshes/kr3r540/collision/link_6.stl"/>
      </geometry>
    </collision>
  </link>
  <!-- Following REP199, this frame shall be use to attach EEF or other equipment -->
  <link name="right_armflange"/>
  <joint name="right_armjoint_a1" type="revolute">
    <origin rpy="0 0 0" xyz="0 0 0.345"/>
    <parent link="right_armbase_link"/>
    <child link="right_armlink_1"/>
    <axis xyz="0 0 -1"/>
    <limit effort="0" lower="-2.9670597283903604" upper="2.9670597283903604" velocity="9.250245035569947"/>
  </joint>
  <joint name="right_armjoint_a2" type="revolute">
    <origin rpy="0 0 0" xyz="0.020 0 0"/>
    <parent link="right_armlink_1"/>
    <child link="right_armlink_2"/>
    <axis xyz="0 1 0"/>
    <limit effort="0" lower="-2.9670597283903604" upper="0.8726646259971648" velocity="9.232791743050003"/>
  </joint>
  <joint name="right_armjoint_a3" type="revolute">
    <origin rpy="0 0 0" xyz="0.260 0 0"/>
    <parent link="right_armlink_2"/>
    <child link="right_armlink_3"/>
    <axis xyz="0 1 0"/>
    <limit effort="0" lower="-1.9198621771937625" upper="2.705260340591211" velocity="9.389871375729493"/>
  </joint>
  <joint name="right_armjoint_a4" type="revolute">
    <origin rpy="0 0 0" xyz="0 0 0.020"/>
    <parent link="right_armlink_3"/>
    <child link="right_armlink_4"/>
    <axis xyz="-1 0 0"/>
    <limit effort="0" lower="-3.0543261909900767" upper="3.0543261909900767" velocity="10.471975511965978"/>
  </joint>
  <joint name="right_armjoint_a5" type="revolute">
    <origin rpy="0 0 0" xyz="0.260 0 0"/>
    <parent link="right_armlink_4"/>
    <child link="right_armlink_5"/>
    <axis xyz="0 1 0"/>
    <limit effort="0" lower="-2.0943951023931953" upper="2.0943951023931953" velocity="10.471975511965978"/>
  </joint>
  <joint name="right_armjoint_a6" type="revolute">
    <origin rpy="0 0 0" xyz="0.075 0 0"/>
    <parent link="right_armlink_5"/>
    <child link="right_armlink_6"/>
    <axis xyz="-1 0 0"/>
    <limit effort="0" lower="-6.1086523819801535" upper="6.1086523819801535" velocity="13.962634015954636"/>
  </joint>
  <joint name="right_armjoint_a6-tool0" type="fixed">
    <parent link="right_armlink_6"/>
    <child link="right_armflange"/>
    <origin rpy="0 0 0" xyz="0 0 0"/>
  </joint>
  <!-- ROS base_link to KUKA $ROBROOT coordinate system transform -->
  <link name="right_armbase"/>
  <joint name="right_armbase_link-base" type="fixed">
    <origin rpy="0 0 0" xyz="0 0 0"/>
    <parent link="right_armbase_link"/>
    <child link="right_armbase"/>
  </joint>
  <!-- This frame corresponds to the $TOOL coordinate system in KUKA KRC controllers -->
  <link name="right_armtool0"/>
  <joint name="right_armflange-tool0" type="fixed">
    <parent link="right_armflange"/>
    <child link="right_armtool0"/>
    <origin rpy="0 1.5707963267948966 0" xyz="0 0 0"/>
  </joint>
  <link name="right_armcell_link">
    <visual>
      <!--                TODO rearrange origins, so that only this link has non-zero origin-->
      <origin rpy="0 0 0" xyz="0 0 0"/>
      <geometry>
        <mesh filename="package://kuka_ready2_educate_support/meshes/whole_cell_binary.stl"/>
      </geometry>
      <material name="gray">
        <color rgba="0.5 0.5 0.5 1"/>
      </material>
    </visual>
    <collision>
      <origin rpy="0 0 0" xyz="-0.0875 -0.052527 1"/>
      <geometry>
        <box size="0.9 1.215 0.03"/>
      </geometry>
    </collision>
  </link>
  <link name="right_armwall_1">
    <collision>
      <origin rpy="0 0 0" xyz="-0.0875 -0.052527 0.995"/>
      <geometry>
        <box size="0.03 1.215 0.84"/>
      </geometry>
    </collision>
  </link>
  <joint name="right_armwall_1_joint" type="fixed">
    <origin rpy="0 0 0" xyz="0.405 0 0.42"/>
    <parent link="right_armcell_link"/>
    <child link="right_armwall_1"/>
  </joint>
  <link name="right_armwall_2">
    <collision>
      <origin rpy="0 0 0" xyz="-0.0875 -0.052527 0.995"/>
      <geometry>
        <box size="0.03 1.215 0.84"/>
      </geometry>
    </collision>
  </link>
  <joint name="right_armwall_2_joint" type="fixed">
    <origin rpy="0 0 0" xyz="-0.405 0 0.42"/>
    <parent link="right_armcell_link"/>
    <child link="right_armwall_2"/>
  </joint>
  <link name="right_armwall_3">
    <collision>
      <origin rpy="0 0 0" xyz="-0.0875 -0.052527 0.995"/>
      <geometry>
        <box size="0.9 0.03 0.84"/>
      </geometry>
    </collision>
  </link>
  <joint name="right_armwall_3_joint" type="fixed">
    <origin rpy="0 0 0" xyz="0 0.58 0.42"/>
    <parent link="right_armcell_link"/>
    <child link="right_armwall_3"/>
  </joint>
  <link name="right_armwall_4">
    <collision>
      <origin rpy="0 0 0" xyz="-0.0875 -0.052527 0.995"/>
      <geometry>
        <box size="0.9 0.03 0.84"/>
      </geometry>
    </collision>
  </link>
  <joint name="right_armwall_4_joint" type="fixed">
    <origin rpy="0 0 0" xyz="0 -0.58 0.42"/>
    <parent link="right_armcell_link"/>
    <child link="right_armwall_4"/>
  </joint>
  <link name="right_armroof">
    <collision>
      <origin rpy="0 0 0" xyz="-0.0875 -0.052527 0.995"/>
      <geometry>
        <box size="0.9 1.215 0.03"/>
      </geometry>
    </collision>
  </link>
  <joint name="right_armroof_joint" type="fixed">
    <origin rpy="0 0 0" xyz="0 0 0.84"/>
    <parent link="right_armcell_link"/>
    <child link="right_armroof"/>
  </joint>
  <link name="right_armcamera">
    <visual>
      <origin rpy="0 0 0" xyz="-0.0875 -0.052527 0.995"/>
      <geometry>
        <box size="0.045 0.053 0.195"/>
      </geometry>
      <material name="gray">
        <color rgba="0.5 0.5 0.5 1"/>
      </material>
    </visual>
    <collision>
      <origin rpy="0 0 0" xyz="-0.0875 -0.052527 0.995"/>
      <geometry>
        <box size="0.045 0.053 0.195"/>
      </geometry>
    </collision>
  </link>
  <joint name="right_armcamera_joint" type="fixed">
    <origin rpy="0 0 0" xyz="-0.0325 0.264 0.7325"/>
    <parent link="right_armcell_link"/>
    <child link="right_armcamera"/>
  </joint>
  <joint name="right_armworld_to_cell" type="fixed">
    <origin rpy="0.0 0.0 0.0" xyz="0 0 1"/>
    <parent link="world"/>
    <child link="right_armcell_link"/>
  </joint>
  <joint name="right_armcell_to_base" type="fixed">
    <origin rpy="0 0 0" xyz="-0.25 -0.0525 0.835"/>
    <parent link="right_armcell_link"/>
    <child link="right_armbase_link"/>
  </joint>
  <link name="left_armbase_link">
    <inertial>
      <mass value="0.01"/>
      <origin xyz="0 0 0"/>
      <inertia ixx="0.001" ixy="0.0" ixz="0.0" iyy="0.001" iyz="0.0" izz="0.001"/>
    </inertial>
    <visual>
      <origin rpy="0 0 0" xyz="0 0 0"/>
      <geometry>
        <mesh filename="file:///home/huang/stogl_workspace/ros_rolling_docker_ws/install/kuka_kr3_support/share/kuka_kr3_support/meshes/kr3r540/visual/base_link.stl"/>
      </geometry>
      <material name="">
        <color rgba="0.5058823529411764 0.47058823529411764 0.38823529411764707 1.0"/>
      </material>
    </visual>
    <collision>
      <origin rpy="0 0 0" xyz="0 0 0"/>
      <geometry>
        <mesh filename="file:///home/huang/stogl_workspace/ros_rolling_docker_ws/install/kuka_kr3_support/share/kuka_kr3_support/meshes/kr3r540/collision/base_link.stl"/>
      </geometry>
    </collision>
  </link>
  <link name="left_armlink_1">
    <inertial>
      <mass value="0.01"/>
      <origin xyz="0 0 0"/>
      <inertia ixx="0.001" ixy="0.0" ixz="0.0" iyy="0.001" iyz="0.0" izz="0.001"/>
    </inertial>
    <visual>
      <origin rpy="0 0 0" xyz="0 0 0"/>
      <geometry>
        <mesh filename="file:///home/huang/stogl_workspace/ros_rolling_docker_ws/install/kuka_kr3_support/share/kuka_kr3_support/meshes/kr3r540/visual/link_1.stl"/>
      </geometry>
      <material name="">
        <color rgba="0.9450980392156862 0.9254901960784314 1.0 1.0"/>
      </material>
    </visual>
    <collision>
      <origin rpy="0 0 0" xyz="0 0 0"/>
      <geometry>
        <mesh filename="file:///home/huang/stogl_workspace/ros_rolling_docker_ws/install/kuka_kr3_support/share/kuka_kr3_support/meshes/kr3r540/collision/link_1.stl"/>
      </geometry>
    </collision>
  </link>
  <link name="left_armlink_2">
    <inertial>
      <mass value="0.01"/>
      <origin xyz="0 0 0"/>
      <inertia ixx="0.001" ixy="0.0" ixz="0.0" iyy="0.001" iyz="0.0" izz="0.001"/>
    </inertial>
    <visual>
      <origin rpy="0 0 0" xyz="0 0 0"/>
      <geometry>
        <mesh filename="file:///home/huang/stogl_workspace/ros_rolling_docker_ws/install/kuka_kr3_support/share/kuka_kr3_support/meshes/kr3r540/visual/link_2.stl"/>
      </geometry>
      <material name="">
        <color rgba="0.9450980392156862 0.9254901960784314 1.0 1.0"/>
      </material>
    </visual>
    <collision>
      <origin rpy="0 0 0" xyz="0 0 0"/>
      <geometry>
        <mesh filename="file:///home/huang/stogl_workspace/ros_rolling_docker_ws/install/kuka_kr3_support/share/kuka_kr3_support/meshes/kr3r540/collision/link_2.stl"/>
      </geometry>
    </collision>
  </link>
  <link name="left_armlink_3">
    <inertial>
      <mass value="0.01"/>
      <origin xyz="0 0 0"/>
      <inertia ixx="0.001" ixy="0.0" ixz="0.0" iyy="0.001" iyz="0.0" izz="0.001"/>
    </inertial>
    <visual>
      <origin rpy="0 0 0" xyz="0 0 0"/>
      <geometry>
        <mesh filename="file:///home/huang/stogl_workspace/ros_rolling_docker_ws/install/kuka_kr3_support/share/kuka_kr3_support/meshes/kr3r540/visual/link_3.stl"/>
      </geometry>
      <material name="">
        <color rgba="0.9450980392156862 0.9254901960784314 1.0 1.0"/>
      </material>
    </visual>
    <collision>
      <origin rpy="0 0 0" xyz="0 0 0"/>
      <geometry>
        <mesh filename="file:///home/huang/stogl_workspace/ros_rolling_docker_ws/install/kuka_kr3_support/share/kuka_kr3_support/meshes/kr3r540/collision/link_3.stl"/>
      </geometry>
    </collision>
  </link>
  <link name="left_armlink_4">
    <inertial>
      <mass value="0.01"/>
      <origin xyz="0 0 0"/>
      <inertia ixx="0.001" ixy="0.0" ixz="0.0" iyy="0.001" iyz="0.0" izz="0.001"/>
    </inertial>
    <visual>
      <origin rpy="0 0 0" xyz="0 0 0"/>
      <geometry>
        <mesh filename="file:///home/huang/stogl_workspace/ros_rolling_docker_ws/install/kuka_kr3_support/share/kuka_kr3_support/meshes/kr3r540/visual/link_4.stl"/>
      </geometry>
      <material name="">
        <color rgba="0.9450980392156862 0.9254901960784314 1.0 1.0"/>
      </material>
    </visual>
    <collision>
      <origin rpy="0 0 0" xyz="0 0 0"/>
      <geometry>
        <mesh filename="file:///home/huang/stogl_workspace/ros_rolling_docker_ws/install/kuka_kr3_support/share/kuka_kr3_support/meshes/kr3r540/collision/link_4.stl"/>
      </geometry>
    </collision>
  </link>
  <link name="left_armlink_5">
    <inertial>
      <mass value="0.01"/>
      <origin xyz="0 0 0"/>
      <inertia ixx="0.001" ixy="0.0" ixz="0.0" iyy="0.001" iyz="0.0" izz="0.001"/>
    </inertial>
    <visual>
      <origin rpy="0 0 0" xyz="0 0 0"/>
      <geometry>
        <mesh filename="file:///home/huang/stogl_workspace/ros_rolling_docker_ws/install/kuka_kr3_support/share/kuka_kr3_support/meshes/kr3r540/visual/link_5.stl"/>
      </geometry>
      <material name="">
        <color rgba="0.9450980392156862 0.9254901960784314 1.0 1.0"/>
      </material>
    </visual>
    <collision>
      <origin rpy="0 0 0" xyz="0 0 0"/>
      <geometry>
        <mesh filename="file:///home/huang/stogl_workspace/ros_rolling_docker_ws/install/kuka_kr3_support/share/kuka_kr3_support/meshes/kr3r540/collision/link_5.stl"/>
      </geometry>
    </collision>
  </link>
  <link name="left_armlink_6">
    <inertial>
      <mass value="0.01"/>
      <origin xyz="0 0 0"/>
      <inertia ixx="0.001" ixy="0.0" ixz="0.0" iyy="0.001" iyz="0.0" izz="0.001"/>
    </inertial>
    <visual>
      <origin rpy="0 0 0" xyz="0 0 0"/>
      <geometry>
        <mesh filename="file:///home/huang/stogl_workspace/ros_rolling_docker_ws/install/kuka_kr3_support/share/kuka_kr3_support/meshes/kr3r540/visual/link_6.stl"/>
      </geometry>
      <material name="">
        <color rgba="0.5058823529411764 0.47058823529411764 0.38823529411764707 1.0"/>
      </material>
    </visual>
    <collision>
      <origin rpy="0 0 0" xyz="0 0 0"/>
      <geometry>
        <mesh filename="file:///home/huang/stogl_workspace/ros_rolling_docker_ws/install/kuka_kr3_support/share/kuka_kr3_support/meshes/kr3r540/collision/link_6.stl"/>
      </geometry>
    </collision>
  </link>
  <!-- Following REP199, this frame shall be use to attach EEF or other equipment -->
  <link name="left_armflange"/>
  <joint name="left_armjoint_a1" type="revolute">
    <origin rpy="0 0 0" xyz="0 0 0.345"/>
    <parent link="left_armbase_link"/>
    <child link="left_armlink_1"/>
    <axis xyz="0 0 -1"/>
    <limit effort="0" lower="-2.9670597283903604" upper="2.9670597283903604" velocity="9.250245035569947"/>
  </joint>
  <joint name="left_armjoint_a2" type="revolute">
    <origin rpy="0 0 0" xyz="0.020 0 0"/>
    <parent link="left_armlink_1"/>
    <child link="left_armlink_2"/>
    <axis xyz="0 1 0"/>
    <limit effort="0" lower="-2.9670597283903604" upper="0.8726646259971648" velocity="9.232791743050003"/>
  </joint>
  <joint name="left_armjoint_a3" type="revolute">
    <origin rpy="0 0 0" xyz="0.260 0 0"/>
    <parent link="left_armlink_2"/>
    <child link="left_armlink_3"/>
    <axis xyz="0 1 0"/>
    <limit effort="0" lower="-1.9198621771937625" upper="2.705260340591211" velocity="9.389871375729493"/>
  </joint>
  <joint name="left_armjoint_a4" type="revolute">
    <origin rpy="0 0 0" xyz="0 0 0.020"/>
    <parent link="left_armlink_3"/>
    <child link="left_armlink_4"/>
    <axis xyz="-1 0 0"/>
    <limit effort="0" lower="-3.0543261909900767" upper="3.0543261909900767" velocity="10.471975511965978"/>
  </joint>
  <joint name="left_armjoint_a5" type="revolute">
    <origin rpy="0 0 0" xyz="0.260 0 0"/>
    <parent link="left_armlink_4"/>
    <child link="left_armlink_5"/>
    <axis xyz="0 1 0"/>
    <limit effort="0" lower="-2.0943951023931953" upper="2.0943951023931953" velocity="10.471975511965978"/>
  </joint>
  <joint name="left_armjoint_a6" type="revolute">
    <origin rpy="0 0 0" xyz="0.075 0 0"/>
    <parent link="left_armlink_5"/>
    <child link="left_armlink_6"/>
    <axis xyz="-1 0 0"/>
    <limit effort="0" lower="-6.1086523819801535" upper="6.1086523819801535" velocity="13.962634015954636"/>
  </joint>
  <joint name="left_armjoint_a6-tool0" type="fixed">
    <parent link="left_armlink_6"/>
    <child link="left_armflange"/>
    <origin rpy="0 0 0" xyz="0 0 0"/>
  </joint>
  <!-- ROS base_link to KUKA $ROBROOT coordinate system transform -->
  <link name="left_armbase"/>
  <joint name="left_armbase_link-base" type="fixed">
    <origin rpy="0 0 0" xyz="0 0 0"/>
    <parent link="left_armbase_link"/>
    <child link="left_armbase"/>
  </joint>
  <!-- This frame corresponds to the $TOOL coordinate system in KUKA KRC controllers -->
  <link name="left_armtool0"/>
  <joint name="left_armflange-tool0" type="fixed">
    <parent link="left_armflange"/>
    <child link="left_armtool0"/>
    <origin rpy="0 1.5707963267948966 0" xyz="0 0 0"/>
  </joint>
  <link name="left_armcell_link">
    <visual>
      <!--                TODO rearrange origins, so that only this link has non-zero origin-->
      <origin rpy="0 0 0" xyz="0 0 0"/>
      <geometry>
        <mesh filename="package://kuka_ready2_educate_support/meshes/whole_cell_binary.stl"/>
      </geometry>
      <material name="gray">
        <color rgba="0.5 0.5 0.5 1"/>
      </material>
    </visual>
    <collision>
      <origin rpy="0 0 0" xyz="-0.0875 -0.052527 1"/>
      <geometry>
        <box size="0.9 1.215 0.03"/>
      </geometry>
    </collision>
  </link>
  <link name="left_armwall_1">
    <collision>
      <origin rpy="0 0 0" xyz="-0.0875 -0.052527 0.995"/>
      <geometry>
        <box size="0.03 1.215 0.84"/>
      </geometry>
    </collision>
  </link>
  <joint name="left_armwall_1_joint" type="fixed">
    <origin rpy="0 0 0" xyz="0.405 0 0.42"/>
    <parent link="left_armcell_link"/>
    <child link="left_armwall_1"/>
  </joint>
  <link name="left_armwall_2">
    <collision>
      <origin rpy="0 0 0" xyz="-0.0875 -0.052527 0.995"/>
      <geometry>
        <box size="0.03 1.215 0.84"/>
      </geometry>
    </collision>
  </link>
  <joint name="left_armwall_2_joint" type="fixed">
    <origin rpy="0 0 0" xyz="-0.405 0 0.42"/>
    <parent link="left_armcell_link"/>
    <child link="left_armwall_2"/>
  </joint>
  <link name="left_armwall_3">
    <collision>
      <origin rpy="0 0 0" xyz="-0.0875 -0.052527 0.995"/>
      <geometry>
        <box size="0.9 0.03 0.84"/>
      </geometry>
    </collision>
  </link>
  <joint name="left_armwall_3_joint" type="fixed">
    <origin rpy="0 0 0" xyz="0 0.58 0.42"/>
    <parent link="left_armcell_link"/>
    <child link="left_armwall_3"/>
  </joint>
  <link name="left_armwall_4">
    <collision>
      <origin rpy="0 0 0" xyz="-0.0875 -0.052527 0.995"/>
      <geometry>
        <box size="0.9 0.03 0.84"/>
      </geometry>
    </collision>
  </link>
  <joint name="left_armwall_4_joint" type="fixed">
    <origin rpy="0 0 0" xyz="0 -0.58 0.42"/>
    <parent link="left_armcell_link"/>
    <child link="left_armwall_4"/>
  </joint>
  <link name="left_armroof">
    <collision>
      <origin rpy="0 0 0" xyz="-0.0875 -0.052527 0.995"/>
      <geometry>
        <box size="0.9 1.215 0.03"/>
      </geometry>
    </collision>
  </link>
  <joint name="left_armroof_joint" type="fixed">
    <origin rpy="0 0 0" xyz="0 0 0.84"/>
    <parent link="left_armcell_link"/>
    <child link="left_armroof"/>
  </joint>
  <link name="left_armcamera">
    <visual>
      <origin rpy="0 0 0" xyz="-0.0875 -0.052527 0.995"/>
      <geometry>
        <box size="0.045 0.053 0.195"/>
      </geometry>
      <material name="gray">
        <color rgba="0.5 0.5 0.5 1"/>
      </material>
    </visual>
    <collision>
      <origin rpy="0 0 0" xyz="-0.0875 -0.052527 0.995"/>
      <geometry>
        <box size="0.045 0.053 0.195"/>
      </geometry>
    </collision>
  </link>
  <joint name="left_armcamera_joint" type="fixed">
    <origin rpy="0 0 0" xyz="-0.0325 0.264 0.7325"/>
    <parent link="left_armcell_link"/>
    <child link="left_armcamera"/>
  </joint>
  <joint name="left_armworld_to_cell" type="fixed">
    <origin rpy="0.0 0.0 0.0" xyz="0 1.5 1"/>
    <parent link="world"/>
    <child link="left_armcell_link"/>
  </joint>
  <joint name="left_armcell_to_base" type="fixed">
    <origin rpy="0 0 0" xyz="-0.25 -0.0525 0.835"/>
    <parent link="left_armcell_link"/>
    <child link="left_armbase_link"/>
  </joint>
  <!-- right arm joints control interface -->
  <!-- <xacro:gazebo-joint joint="$(arg arm_id_1)_joint1" transmission="hardware_interface/PositionJointInterface" />
    <xacro:gazebo-joint joint="$(arg arm_id_1)_joint2" transmission="hardware_interface/PositionJointInterface" />
    <xacro:gazebo-joint joint="$(arg arm_id_1)_joint3" transmission="hardware_interface/PositionJointInterface" />
    <xacro:gazebo-joint joint="$(arg arm_id_1)_joint4" transmission="hardware_interface/PositionJointInterface" />
    <xacro:gazebo-joint joint="$(arg arm_id_1)_joint5" transmission="hardware_interface/PositionJointInterface" />
    <xacro:gazebo-joint joint="$(arg arm_id_1)_joint6" transmission="hardware_interface/PositionJointInterface" />
    <xacro:gazebo-joint joint="$(arg arm_id_1)_joint7" transmission="hardware_interface/PositionJointInterface" /> -->
  <!-- left arm joints control interface -->
  <!-- <xacro:gazebo-joint joint="$(arg arm_id_2)_joint1" transmission="hardware_interface/PositionJointInterface" />
    <xacro:gazebo-joint joint="$(arg arm_id_2)_joint2" transmission="hardware_interface/PositionJointInterface" />
    <xacro:gazebo-joint joint="$(arg arm_id_2)_joint3" transmission="hardware_interface/PositionJointInterface" />
    <xacro:gazebo-joint joint="$(arg arm_id_2)_joint4" transmission="hardware_interface/PositionJointInterface" />
    <xacro:gazebo-joint joint="$(arg arm_id_2)_joint5" transmission="hardware_interface/PositionJointInterface" />
    <xacro:gazebo-joint joint="$(arg arm_id_2)_joint6" transmission="hardware_interface/PositionJointInterface" />
    <xacro:gazebo-joint joint="$(arg arm_id_2)_joint7" transmission="hardware_interface/PositionJointInterface" /> -->
  <!-- right hand joints control interface -->
  <!-- <xacro:gazebo-joint joint="$(arg arm_id_1)_finger_joint1" transmission="hardware_interface/EffortJointInterface" />
    <xacro:gazebo-joint joint="$(arg arm_id_1)_finger_joint2" transmission="hardware_interface/EffortJointInterface" /> -->
  <!-- left hand joints control interface -->
  <!-- <xacro:gazebo-joint joint="$(arg arm_id_2)_finger_joint1" transmission="hardware_interface/EffortJointInterface" /> -->
  <!-- <xacro:gazebo-joint joint="$(arg arm_id_2)_finger_joint2" transmission="hardware_interface/EffortJointInterface" /> -->
  <!-- load ros_control plugin -->
  <!-- <gazebo>
        <plugin name="gazebo_ros_control" filename="libgazebo_ros_control.so"/>
    </gazebo> -->
</robot>
